balances for Щепин К. М.17020@ differs more than 10
balances for Щепин К. М.17020@ differs more than 10
balances for Щепин К. М.17020@ differs more than 10
WARNING 2017-07-31 13:27:50,708 balances for Щепин К. М.17020@ differs more than 10
ERROR 2017-07-31 13:31:05,400 Internal Server Error: /bank/add_transaction/lecture/
Traceback (most recent call last):
  File "/Users/Insolia/Code/Python/bank_2.0/env/bank_2.0_venv/lib/python3.6/site-packages/django/db/models/fields/__init__.py", line 1254, in to_python
    parsed = parse_date(value)
  File "/Users/Insolia/Code/Python/bank_2.0/env/bank_2.0_venv/lib/python3.6/site-packages/django/utils/dateparse.py", line 64, in parse_date
    return datetime.date(**kw)
ValueError: year 0 is out of range

During handling of the above exception, another exception occurred:

Traceback (most recent call last):
  File "/Users/Insolia/Code/Python/bank_2.0/env/bank_2.0_venv/lib/python3.6/site-packages/django/core/handlers/exception.py", line 41, in inner
    response = get_response(request)
  File "/Users/Insolia/Code/Python/bank_2.0/env/bank_2.0_venv/lib/python3.6/site-packages/django/core/handlers/base.py", line 249, in _legacy_get_response
    response = self._get_response(request)
  File "/Users/Insolia/Code/Python/bank_2.0/env/bank_2.0_venv/lib/python3.6/site-packages/django/core/handlers/base.py", line 187, in _get_response
    response = self.process_exception_by_middleware(e, request)
  File "/Users/Insolia/Code/Python/bank_2.0/env/bank_2.0_venv/lib/python3.6/site-packages/django/core/handlers/base.py", line 185, in _get_response
    response = wrapped_callback(request, *callback_args, **callback_kwargs)
  File "/Users/Insolia/Code/Python/bank_2.0/env/bank_2.0_venv/lib/python3.6/site-packages/django/contrib/auth/decorators.py", line 23, in _wrapped_view
    return view_func(request, *args, **kwargs)
  File "/Users/Insolia/Code/Python/bank_2.0/bank_app/bank/views.py", line 66, in add_transaction
    created_transaction = controller.get_transaction_from_form_data(formset.cleaned_data, update_of)
  File "/Users/Insolia/Code/Python/bank_2.0/bank_app/bank/controls/transaction_controllers/LectureTransactionController.py", line 44, in get_transaction_from_form_data
    new_transaction, attendance_block_name=attendance_block_name)
  File "/Users/Insolia/Code/Python/bank_2.0/bank_app/bank/models/Attendance.py", line 26, in new_attendance
    new_att.save()
  File "/Users/Insolia/Code/Python/bank_2.0/env/bank_2.0_venv/lib/python3.6/site-packages/django/db/models/base.py", line 806, in save
    force_update=force_update, update_fields=update_fields)
  File "/Users/Insolia/Code/Python/bank_2.0/env/bank_2.0_venv/lib/python3.6/site-packages/django/db/models/base.py", line 836, in save_base
    updated = self._save_table(raw, cls, force_insert, force_update, using, update_fields)
  File "/Users/Insolia/Code/Python/bank_2.0/env/bank_2.0_venv/lib/python3.6/site-packages/django/db/models/base.py", line 922, in _save_table
    result = self._do_insert(cls._base_manager, using, fields, update_pk, raw)
  File "/Users/Insolia/Code/Python/bank_2.0/env/bank_2.0_venv/lib/python3.6/site-packages/django/db/models/base.py", line 961, in _do_insert
    using=using, raw=raw)
  File "/Users/Insolia/Code/Python/bank_2.0/env/bank_2.0_venv/lib/python3.6/site-packages/django/db/models/manager.py", line 85, in manager_method
    return getattr(self.get_queryset(), name)(*args, **kwargs)
  File "/Users/Insolia/Code/Python/bank_2.0/env/bank_2.0_venv/lib/python3.6/site-packages/django/db/models/query.py", line 1061, in _insert
    return query.get_compiler(using=using).execute_sql(return_id)
  File "/Users/Insolia/Code/Python/bank_2.0/env/bank_2.0_venv/lib/python3.6/site-packages/django/db/models/sql/compiler.py", line 1098, in execute_sql
    for sql, params in self.as_sql():
  File "/Users/Insolia/Code/Python/bank_2.0/env/bank_2.0_venv/lib/python3.6/site-packages/django/db/models/sql/compiler.py", line 1051, in as_sql
    for obj in self.query.objs
  File "/Users/Insolia/Code/Python/bank_2.0/env/bank_2.0_venv/lib/python3.6/site-packages/django/db/models/sql/compiler.py", line 1051, in <listcomp>
    for obj in self.query.objs
  File "/Users/Insolia/Code/Python/bank_2.0/env/bank_2.0_venv/lib/python3.6/site-packages/django/db/models/sql/compiler.py", line 1050, in <listcomp>
    [self.prepare_value(field, self.pre_save_val(field, obj)) for field in fields]
  File "/Users/Insolia/Code/Python/bank_2.0/env/bank_2.0_venv/lib/python3.6/site-packages/django/db/models/sql/compiler.py", line 990, in prepare_value
    value = field.get_db_prep_save(value, connection=self.connection)
  File "/Users/Insolia/Code/Python/bank_2.0/env/bank_2.0_venv/lib/python3.6/site-packages/django/db/models/fields/__init__.py", line 766, in get_db_prep_save
    prepared=False)
  File "/Users/Insolia/Code/Python/bank_2.0/env/bank_2.0_venv/lib/python3.6/site-packages/django/db/models/fields/__init__.py", line 1297, in get_db_prep_value
    value = self.get_prep_value(value)
  File "/Users/Insolia/Code/Python/bank_2.0/env/bank_2.0_venv/lib/python3.6/site-packages/django/db/models/fields/__init__.py", line 1292, in get_prep_value
    return self.to_python(value)
  File "/Users/Insolia/Code/Python/bank_2.0/env/bank_2.0_venv/lib/python3.6/site-packages/django/db/models/fields/__init__.py", line 1261, in to_python
    params={'value': value},
django.core.exceptions.ValidationError: ["'0000-07-31' value has the correct format (YYYY-MM-DD) but it is an invalid date."]
ERROR 2017-07-31 13:31:05,812 "POST /bank/add_transaction/lecture/ HTTP/1.1" 500 272202
ERROR 2017-07-31 13:47:07,729 Internal Server Error: /bank_api/money/
Traceback (most recent call last):
  File "/Users/Insolia/Code/Python/bank_2.0/env/bank_2.0_venv/lib/python3.6/site-packages/django/core/handlers/exception.py", line 41, in inner
    response = get_response(request)
  File "/Users/Insolia/Code/Python/bank_2.0/env/bank_2.0_venv/lib/python3.6/site-packages/django/core/handlers/base.py", line 249, in _legacy_get_response
    response = self._get_response(request)
  File "/Users/Insolia/Code/Python/bank_2.0/env/bank_2.0_venv/lib/python3.6/site-packages/django/core/handlers/base.py", line 187, in _get_response
    response = self.process_exception_by_middleware(e, request)
  File "/Users/Insolia/Code/Python/bank_2.0/env/bank_2.0_venv/lib/python3.6/site-packages/django/core/handlers/base.py", line 185, in _get_response
    response = wrapped_callback(request, *callback_args, **callback_kwargs)
  File "/Users/Insolia/Code/Python/bank_2.0/env/bank_2.0_venv/lib/python3.6/site-packages/django/views/decorators/csrf.py", line 58, in wrapped_view
    return view_func(*args, **kwargs)
  File "/Users/Insolia/Code/Python/bank_2.0/bank_app/bank_api/views.py", line 69, in get_students_money
    for money in Money.objects.filter(counted=True, related_transaction__creator__groups__in=[UserGroups.staff.value]):
  File "/Users/Insolia/Code/Python/bank_2.0/env/bank_2.0_venv/lib/python3.6/site-packages/django/db/models/manager.py", line 85, in manager_method
    return getattr(self.get_queryset(), name)(*args, **kwargs)
  File "/Users/Insolia/Code/Python/bank_2.0/env/bank_2.0_venv/lib/python3.6/site-packages/django/db/models/query.py", line 782, in filter
    return self._filter_or_exclude(False, *args, **kwargs)
  File "/Users/Insolia/Code/Python/bank_2.0/env/bank_2.0_venv/lib/python3.6/site-packages/django/db/models/query.py", line 800, in _filter_or_exclude
    clone.query.add_q(Q(*args, **kwargs))
  File "/Users/Insolia/Code/Python/bank_2.0/env/bank_2.0_venv/lib/python3.6/site-packages/django/db/models/sql/query.py", line 1261, in add_q
    clause, _ = self._add_q(q_object, self.used_aliases)
  File "/Users/Insolia/Code/Python/bank_2.0/env/bank_2.0_venv/lib/python3.6/site-packages/django/db/models/sql/query.py", line 1287, in _add_q
    allow_joins=allow_joins, split_subq=split_subq,
  File "/Users/Insolia/Code/Python/bank_2.0/env/bank_2.0_venv/lib/python3.6/site-packages/django/db/models/sql/query.py", line 1217, in build_filter
    condition = lookup_class(lhs, value)
  File "/Users/Insolia/Code/Python/bank_2.0/env/bank_2.0_venv/lib/python3.6/site-packages/django/db/models/lookups.py", line 24, in __init__
    self.rhs = self.get_prep_lookup()
  File "/Users/Insolia/Code/Python/bank_2.0/env/bank_2.0_venv/lib/python3.6/site-packages/django/db/models/fields/related_lookups.py", line 56, in get_prep_lookup
    self.rhs = [target_field.get_prep_value(v) for v in self.rhs]
  File "/Users/Insolia/Code/Python/bank_2.0/env/bank_2.0_venv/lib/python3.6/site-packages/django/db/models/fields/related_lookups.py", line 56, in <listcomp>
    self.rhs = [target_field.get_prep_value(v) for v in self.rhs]
  File "/Users/Insolia/Code/Python/bank_2.0/env/bank_2.0_venv/lib/python3.6/site-packages/django/db/models/fields/__init__.py", line 962, in get_prep_value
    return int(value)
ValueError: invalid literal for int() with base 10: 'staff'
ERROR 2017-07-31 13:47:08,041 "GET /bank_api/money/ HTTP/1.1" 500 125060
ERROR 2017-07-31 13:48:20,303 Internal Server Error: /bank_api/money/
Traceback (most recent call last):
  File "/Users/Insolia/Code/Python/bank_2.0/env/bank_2.0_venv/lib/python3.6/site-packages/django/core/handlers/exception.py", line 41, in inner
    response = get_response(request)
  File "/Users/Insolia/Code/Python/bank_2.0/env/bank_2.0_venv/lib/python3.6/site-packages/django/core/handlers/base.py", line 249, in _legacy_get_response
    response = self._get_response(request)
  File "/Users/Insolia/Code/Python/bank_2.0/env/bank_2.0_venv/lib/python3.6/site-packages/django/core/handlers/base.py", line 187, in _get_response
    response = self.process_exception_by_middleware(e, request)
  File "/Users/Insolia/Code/Python/bank_2.0/env/bank_2.0_venv/lib/python3.6/site-packages/django/core/handlers/base.py", line 185, in _get_response
    response = wrapped_callback(request, *callback_args, **callback_kwargs)
  File "/Users/Insolia/Code/Python/bank_2.0/env/bank_2.0_venv/lib/python3.6/site-packages/django/views/decorators/csrf.py", line 58, in wrapped_view
    return view_func(*args, **kwargs)
  File "/Users/Insolia/Code/Python/bank_2.0/bank_app/bank_api/views.py", line 69, in get_students_money
    for money in Money.objects.filter(counted=True, related_transaction__creator__groups__contains=[UserGroups.staff.value]):
  File "/Users/Insolia/Code/Python/bank_2.0/env/bank_2.0_venv/lib/python3.6/site-packages/django/db/models/manager.py", line 85, in manager_method
    return getattr(self.get_queryset(), name)(*args, **kwargs)
  File "/Users/Insolia/Code/Python/bank_2.0/env/bank_2.0_venv/lib/python3.6/site-packages/django/db/models/query.py", line 782, in filter
    return self._filter_or_exclude(False, *args, **kwargs)
  File "/Users/Insolia/Code/Python/bank_2.0/env/bank_2.0_venv/lib/python3.6/site-packages/django/db/models/query.py", line 800, in _filter_or_exclude
    clone.query.add_q(Q(*args, **kwargs))
  File "/Users/Insolia/Code/Python/bank_2.0/env/bank_2.0_venv/lib/python3.6/site-packages/django/db/models/sql/query.py", line 1261, in add_q
    clause, _ = self._add_q(q_object, self.used_aliases)
  File "/Users/Insolia/Code/Python/bank_2.0/env/bank_2.0_venv/lib/python3.6/site-packages/django/db/models/sql/query.py", line 1287, in _add_q
    allow_joins=allow_joins, split_subq=split_subq,
  File "/Users/Insolia/Code/Python/bank_2.0/env/bank_2.0_venv/lib/python3.6/site-packages/django/db/models/sql/query.py", line 1212, in build_filter
    raise FieldError('Related Field got invalid lookup: {}'.format(lookups[0]))
django.core.exceptions.FieldError: Related Field got invalid lookup: contains
ERROR 2017-07-31 13:48:20,531 "GET /bank_api/money/ HTTP/1.1" 500 108185
ERROR 2017-07-31 13:48:40,723 Internal Server Error: /bank_api/money/
Traceback (most recent call last):
  File "/Users/Insolia/Code/Python/bank_2.0/env/bank_2.0_venv/lib/python3.6/site-packages/django/core/handlers/exception.py", line 41, in inner
    response = get_response(request)
  File "/Users/Insolia/Code/Python/bank_2.0/env/bank_2.0_venv/lib/python3.6/site-packages/django/core/handlers/base.py", line 249, in _legacy_get_response
    response = self._get_response(request)
  File "/Users/Insolia/Code/Python/bank_2.0/env/bank_2.0_venv/lib/python3.6/site-packages/django/core/handlers/base.py", line 187, in _get_response
    response = self.process_exception_by_middleware(e, request)
  File "/Users/Insolia/Code/Python/bank_2.0/env/bank_2.0_venv/lib/python3.6/site-packages/django/core/handlers/base.py", line 185, in _get_response
    response = wrapped_callback(request, *callback_args, **callback_kwargs)
  File "/Users/Insolia/Code/Python/bank_2.0/env/bank_2.0_venv/lib/python3.6/site-packages/django/views/decorators/csrf.py", line 58, in wrapped_view
    return view_func(*args, **kwargs)
  File "/Users/Insolia/Code/Python/bank_2.0/bank_app/bank_api/views.py", line 69, in get_students_money
    for money in Money.objects.filter(counted=True, related_transaction__creator__groups__in=UserGroups.staff.value):
  File "/Users/Insolia/Code/Python/bank_2.0/env/bank_2.0_venv/lib/python3.6/site-packages/django/db/models/manager.py", line 85, in manager_method
    return getattr(self.get_queryset(), name)(*args, **kwargs)
  File "/Users/Insolia/Code/Python/bank_2.0/env/bank_2.0_venv/lib/python3.6/site-packages/django/db/models/query.py", line 782, in filter
    return self._filter_or_exclude(False, *args, **kwargs)
  File "/Users/Insolia/Code/Python/bank_2.0/env/bank_2.0_venv/lib/python3.6/site-packages/django/db/models/query.py", line 800, in _filter_or_exclude
    clone.query.add_q(Q(*args, **kwargs))
  File "/Users/Insolia/Code/Python/bank_2.0/env/bank_2.0_venv/lib/python3.6/site-packages/django/db/models/sql/query.py", line 1261, in add_q
    clause, _ = self._add_q(q_object, self.used_aliases)
  File "/Users/Insolia/Code/Python/bank_2.0/env/bank_2.0_venv/lib/python3.6/site-packages/django/db/models/sql/query.py", line 1287, in _add_q
    allow_joins=allow_joins, split_subq=split_subq,
  File "/Users/Insolia/Code/Python/bank_2.0/env/bank_2.0_venv/lib/python3.6/site-packages/django/db/models/sql/query.py", line 1212, in build_filter
    raise FieldError('Related Field got invalid lookup: {}'.format(lookups[0]))
django.core.exceptions.FieldError: Related Field got invalid lookup: contains
ERROR 2017-07-31 13:48:41,212 "GET /bank_api/money/ HTTP/1.1" 500 108169
ERROR 2017-07-31 13:48:47,026 Internal Server Error: /bank_api/money/
Traceback (most recent call last):
  File "/Users/Insolia/Code/Python/bank_2.0/env/bank_2.0_venv/lib/python3.6/site-packages/django/core/handlers/exception.py", line 41, in inner
    response = get_response(request)
  File "/Users/Insolia/Code/Python/bank_2.0/env/bank_2.0_venv/lib/python3.6/site-packages/django/core/handlers/base.py", line 249, in _legacy_get_response
    response = self._get_response(request)
  File "/Users/Insolia/Code/Python/bank_2.0/env/bank_2.0_venv/lib/python3.6/site-packages/django/core/handlers/base.py", line 187, in _get_response
    response = self.process_exception_by_middleware(e, request)
  File "/Users/Insolia/Code/Python/bank_2.0/env/bank_2.0_venv/lib/python3.6/site-packages/django/core/handlers/base.py", line 185, in _get_response
    response = wrapped_callback(request, *callback_args, **callback_kwargs)
  File "/Users/Insolia/Code/Python/bank_2.0/env/bank_2.0_venv/lib/python3.6/site-packages/django/views/decorators/csrf.py", line 58, in wrapped_view
    return view_func(*args, **kwargs)
  File "/Users/Insolia/Code/Python/bank_2.0/bank_app/bank_api/views.py", line 69, in get_students_money
    for money in Money.objects.filter(counted=True, related_transaction__creator__groups__in=UserGroups.staff.value):
  File "/Users/Insolia/Code/Python/bank_2.0/env/bank_2.0_venv/lib/python3.6/site-packages/django/db/models/manager.py", line 85, in manager_method
    return getattr(self.get_queryset(), name)(*args, **kwargs)
  File "/Users/Insolia/Code/Python/bank_2.0/env/bank_2.0_venv/lib/python3.6/site-packages/django/db/models/query.py", line 782, in filter
    return self._filter_or_exclude(False, *args, **kwargs)
  File "/Users/Insolia/Code/Python/bank_2.0/env/bank_2.0_venv/lib/python3.6/site-packages/django/db/models/query.py", line 800, in _filter_or_exclude
    clone.query.add_q(Q(*args, **kwargs))
  File "/Users/Insolia/Code/Python/bank_2.0/env/bank_2.0_venv/lib/python3.6/site-packages/django/db/models/sql/query.py", line 1261, in add_q
    clause, _ = self._add_q(q_object, self.used_aliases)
  File "/Users/Insolia/Code/Python/bank_2.0/env/bank_2.0_venv/lib/python3.6/site-packages/django/db/models/sql/query.py", line 1287, in _add_q
    allow_joins=allow_joins, split_subq=split_subq,
  File "/Users/Insolia/Code/Python/bank_2.0/env/bank_2.0_venv/lib/python3.6/site-packages/django/db/models/sql/query.py", line 1217, in build_filter
    condition = lookup_class(lhs, value)
  File "/Users/Insolia/Code/Python/bank_2.0/env/bank_2.0_venv/lib/python3.6/site-packages/django/db/models/lookups.py", line 24, in __init__
    self.rhs = self.get_prep_lookup()
  File "/Users/Insolia/Code/Python/bank_2.0/env/bank_2.0_venv/lib/python3.6/site-packages/django/db/models/fields/related_lookups.py", line 56, in get_prep_lookup
    self.rhs = [target_field.get_prep_value(v) for v in self.rhs]
  File "/Users/Insolia/Code/Python/bank_2.0/env/bank_2.0_venv/lib/python3.6/site-packages/django/db/models/fields/related_lookups.py", line 56, in <listcomp>
    self.rhs = [target_field.get_prep_value(v) for v in self.rhs]
  File "/Users/Insolia/Code/Python/bank_2.0/env/bank_2.0_venv/lib/python3.6/site-packages/django/db/models/fields/__init__.py", line 962, in get_prep_value
    return int(value)
ValueError: invalid literal for int() with base 10: 's'
ERROR 2017-07-31 13:48:47,398 "GET /bank_api/money/ HTTP/1.1" 500 125149
ERROR 2017-08-02 12:01:15,657 Internal Server Error: /bank/
Traceback (most recent call last):
  File "/Users/Insolia/Code/Python/bank_2.0/env/bank_2.0_venv/lib/python3.6/site-packages/django/core/handlers/exception.py", line 41, in inner
    response = get_response(request)
  File "/Users/Insolia/Code/Python/bank_2.0/env/bank_2.0_venv/lib/python3.6/site-packages/django/core/handlers/base.py", line 249, in _legacy_get_response
    response = self._get_response(request)
  File "/Users/Insolia/Code/Python/bank_2.0/env/bank_2.0_venv/lib/python3.6/site-packages/django/core/handlers/base.py", line 187, in _get_response
    response = self.process_exception_by_middleware(e, request)
  File "/Users/Insolia/Code/Python/bank_2.0/env/bank_2.0_venv/lib/python3.6/site-packages/django/core/handlers/base.py", line 185, in _get_response
    response = wrapped_callback(request, *callback_args, **callback_kwargs)
  File "/Users/Insolia/Code/Python/bank_2.0/env/bank_2.0_venv/lib/python3.6/site-packages/django/contrib/auth/decorators.py", line 23, in _wrapped_view
    return view_func(request, *args, **kwargs)
  File "/Users/Insolia/Code/Python/bank_2.0/bank_app/bank/views.py", line 26, in index
    log.info("index page request from {}".format(request.user.account.long_name()))
  File "/Users/Insolia/Code/Python/bank_2.0/env/bank_2.0_venv/lib/python3.6/site-packages/django/utils/functional.py", line 239, in inner
    return func(self._wrapped, *args)
  File "/Users/Insolia/Code/Python/bank_2.0/env/bank_2.0_venv/lib/python3.6/site-packages/django/db/models/fields/related_descriptors.py", line 406, in __get__
    self.related.get_accessor_name()
django.db.models.fields.related_descriptors.RelatedObjectDoesNotExist: User has no account.
ERROR 2017-08-02 12:01:15,800 "GET /bank/ HTTP/1.1" 500 80469
ERROR 2017-08-02 12:02:48,657 Internal Server Error: /bank/
Traceback (most recent call last):
  File "/Users/Insolia/Code/Python/bank_2.0/env/bank_2.0_venv/lib/python3.6/site-packages/django/core/handlers/exception.py", line 41, in inner
    response = get_response(request)
  File "/Users/Insolia/Code/Python/bank_2.0/env/bank_2.0_venv/lib/python3.6/site-packages/django/core/handlers/base.py", line 249, in _legacy_get_response
    response = self._get_response(request)
  File "/Users/Insolia/Code/Python/bank_2.0/env/bank_2.0_venv/lib/python3.6/site-packages/django/core/handlers/base.py", line 187, in _get_response
    response = self.process_exception_by_middleware(e, request)
  File "/Users/Insolia/Code/Python/bank_2.0/env/bank_2.0_venv/lib/python3.6/site-packages/django/core/handlers/base.py", line 185, in _get_response
    response = wrapped_callback(request, *callback_args, **callback_kwargs)
  File "/Users/Insolia/Code/Python/bank_2.0/env/bank_2.0_venv/lib/python3.6/site-packages/django/contrib/auth/decorators.py", line 23, in _wrapped_view
    return view_func(request, *args, **kwargs)
  File "/Users/Insolia/Code/Python/bank_2.0/bank_app/bank/views.py", line 28, in index
    print(datetime.date.today() - FIRST_DAY_DATE)
TypeError: unsupported operand type(s) for -: 'datetime.date' and 'datetime.datetime'
ERROR 2017-08-02 12:02:48,762 "GET /bank/ HTTP/1.1" 500 73020
ERROR 2017-08-10 01:07:01,081 Internal Server Error: /bank/study_stats/
Traceback (most recent call last):
  File "/Users/Insolia/Code/Python/bank_2.0/env/bank_2.0_venv/lib/python3.6/site-packages/django/core/handlers/exception.py", line 41, in inner
    response = get_response(request)
  File "/Users/Insolia/Code/Python/bank_2.0/env/bank_2.0_venv/lib/python3.6/site-packages/django/core/handlers/base.py", line 249, in _legacy_get_response
    response = self._get_response(request)
  File "/Users/Insolia/Code/Python/bank_2.0/env/bank_2.0_venv/lib/python3.6/site-packages/django/core/handlers/base.py", line 187, in _get_response
    response = self.process_exception_by_middleware(e, request)
  File "/Users/Insolia/Code/Python/bank_2.0/env/bank_2.0_venv/lib/python3.6/site-packages/django/core/handlers/base.py", line 185, in _get_response
    response = wrapped_callback(request, *callback_args, **callback_kwargs)
  File "/Users/Insolia/Code/Python/bank_2.0/bank_app/bank/views.py", line 222, in study_stats
    return render(request, 'bank/study_stats.html', render_dict)
  File "/Users/Insolia/Code/Python/bank_2.0/env/bank_2.0_venv/lib/python3.6/site-packages/django/shortcuts.py", line 30, in render
    content = loader.render_to_string(template_name, context, request, using=using)
  File "/Users/Insolia/Code/Python/bank_2.0/env/bank_2.0_venv/lib/python3.6/site-packages/django/template/loader.py", line 68, in render_to_string
    return template.render(context, request)
  File "/Users/Insolia/Code/Python/bank_2.0/env/bank_2.0_venv/lib/python3.6/site-packages/django/template/backends/django.py", line 66, in render
    return self.template.render(context)
  File "/Users/Insolia/Code/Python/bank_2.0/env/bank_2.0_venv/lib/python3.6/site-packages/django/template/base.py", line 207, in render
    return self._render(context)
  File "/Users/Insolia/Code/Python/bank_2.0/env/bank_2.0_venv/lib/python3.6/site-packages/django/template/base.py", line 199, in _render
    return self.nodelist.render(context)
  File "/Users/Insolia/Code/Python/bank_2.0/env/bank_2.0_venv/lib/python3.6/site-packages/django/template/base.py", line 990, in render
    bit = node.render_annotated(context)
  File "/Users/Insolia/Code/Python/bank_2.0/env/bank_2.0_venv/lib/python3.6/site-packages/django/template/base.py", line 957, in render_annotated
    return self.render(context)
  File "/Users/Insolia/Code/Python/bank_2.0/env/bank_2.0_venv/lib/python3.6/site-packages/django/template/defaulttags.py", line 216, in render
    nodelist.append(node.render_annotated(context))
  File "/Users/Insolia/Code/Python/bank_2.0/env/bank_2.0_venv/lib/python3.6/site-packages/django/template/base.py", line 957, in render_annotated
    return self.render(context)
  File "/Users/Insolia/Code/Python/bank_2.0/env/bank_2.0_venv/lib/python3.6/site-packages/django/template/defaulttags.py", line 458, in render
    url = reverse(view_name, args=args, kwargs=kwargs, current_app=current_app)
  File "/Users/Insolia/Code/Python/bank_2.0/env/bank_2.0_venv/lib/python3.6/site-packages/django/urls/base.py", line 91, in reverse
    return force_text(iri_to_uri(resolver._reverse_with_prefix(view, prefix, *args, **kwargs)))
  File "/Users/Insolia/Code/Python/bank_2.0/env/bank_2.0_venv/lib/python3.6/site-packages/django/urls/resolvers.py", line 497, in _reverse_with_prefix
    raise NoReverseMatch(msg)
django.urls.exceptions.NoReverseMatch: Reverse for 'user' with arguments '('',)' not found. 1 pattern(s) tried: ['bank/user/(?P<username>.+)/$']
ERROR 2017-08-10 01:07:01,763 "GET /bank/study_stats/ HTTP/1.1" 500 203791
ERROR 2017-08-11 14:14:22,610 "GET /static/django-bootstrap/jquery.js HTTP/1.1" 500 59
ERROR 2017-08-12 15:19:11,301 Internal Server Error: /bank/add_transaction/exam/
Traceback (most recent call last):
  File "/Users/Insolia/Code/Python/bank_2.0/env/bank_2.0_venv/lib/python3.6/site-packages/django/core/handlers/exception.py", line 41, in inner
    response = get_response(request)
  File "/Users/Insolia/Code/Python/bank_2.0/env/bank_2.0_venv/lib/python3.6/site-packages/django/core/handlers/base.py", line 249, in _legacy_get_response
    response = self._get_response(request)
  File "/Users/Insolia/Code/Python/bank_2.0/env/bank_2.0_venv/lib/python3.6/site-packages/django/core/handlers/base.py", line 187, in _get_response
    response = self.process_exception_by_middleware(e, request)
  File "/Users/Insolia/Code/Python/bank_2.0/env/bank_2.0_venv/lib/python3.6/site-packages/django/core/handlers/base.py", line 185, in _get_response
    response = wrapped_callback(request, *callback_args, **callback_kwargs)
  File "/Users/Insolia/Code/Python/bank_2.0/env/bank_2.0_venv/lib/python3.6/site-packages/django/contrib/auth/decorators.py", line 23, in _wrapped_view
    return view_func(request, *args, **kwargs)
  File "/Users/Insolia/Code/Python/bank_2.0/bank_app/bank/views.py", line 71, in add_transaction
    created_transaction = controller.get_transaction_from_form_data(formset.cleaned_data, update_of)
  File "/Users/Insolia/Code/Python/bank_2.0/bank_app/bank/controls/transaction_controllers/ExamTransactionController.py", line 35, in get_transaction_from_form_data
    reward = ExamTransactionController._get_exam_reward(value,scores)
  File "/Users/Insolia/Code/Python/bank_2.0/bank_app/bank/controls/transaction_controllers/ExamTransactionController.py", line 45, in _get_exam_reward
    sum_normalized_score = sum([math.sqrt(s) for s in scores])
  File "/Users/Insolia/Code/Python/bank_2.0/bank_app/bank/controls/transaction_controllers/ExamTransactionController.py", line 45, in <listcomp>
    sum_normalized_score = sum([math.sqrt(s) for s in scores])
ValueError: math domain error
ERROR 2017-08-12 15:19:11,490 "POST /bank/add_transaction/exam/ HTTP/1.1" 500 191904
ERROR 2017-08-15 13:17:45,845 Invalid HTTP_HOST header: '127.0.0.1:8000'. You may need to add '127.0.0.1' to ALLOWED_HOSTS.
ERROR 2017-08-15 13:21:33,286 Internal Server Error: /bank_api/auth
Traceback (most recent call last):
  File "/Users/Insolia/Code/Python/bank_2.0/env/bank_2.0_venv/lib/python3.6/site-packages/django/core/handlers/exception.py", line 41, in inner
    response = get_response(request)
  File "/Users/Insolia/Code/Python/bank_2.0/env/bank_2.0_venv/lib/python3.6/site-packages/django/core/handlers/base.py", line 244, in _legacy_get_response
    response = middleware_method(request)
  File "/Users/Insolia/Code/Python/bank_2.0/env/bank_2.0_venv/lib/python3.6/site-packages/django/middleware/common.py", line 63, in process_request
    path = self.get_full_path_with_slash(request)
  File "/Users/Insolia/Code/Python/bank_2.0/env/bank_2.0_venv/lib/python3.6/site-packages/django/middleware/common.py", line 101, in get_full_path_with_slash
    'url': request.get_host() + new_path,
RuntimeError: You called this URL via POST, but the URL doesn't end in a slash and you have APPEND_SLASH set. Django can't redirect to the slash URL while maintaining POST data. Change your form to point to 127.0.0.1:8000/bank_api/auth/ (note the trailing slash), or set APPEND_SLASH=False in your Django settings.
ERROR 2017-08-15 13:21:33,363 "POST /bank_api/auth HTTP/1.1" 500 62330
ERROR 2017-08-15 13:22:34,480 Internal Server Error: /bank_api/auth/
Traceback (most recent call last):
  File "/Users/Insolia/Code/Python/bank_2.0/env/bank_2.0_venv/lib/python3.6/site-packages/django/core/handlers/exception.py", line 41, in inner
    response = get_response(request)
  File "/Users/Insolia/Code/Python/bank_2.0/env/bank_2.0_venv/lib/python3.6/site-packages/django/core/handlers/base.py", line 249, in _legacy_get_response
    response = self._get_response(request)
  File "/Users/Insolia/Code/Python/bank_2.0/env/bank_2.0_venv/lib/python3.6/site-packages/django/core/handlers/base.py", line 187, in _get_response
    response = self.process_exception_by_middleware(e, request)
  File "/Users/Insolia/Code/Python/bank_2.0/env/bank_2.0_venv/lib/python3.6/site-packages/django/core/handlers/base.py", line 185, in _get_response
    response = wrapped_callback(request, *callback_args, **callback_kwargs)
  File "/Users/Insolia/Code/Python/bank_2.0/env/bank_2.0_venv/lib/python3.6/site-packages/django/views/decorators/csrf.py", line 58, in wrapped_view
    return view_func(*args, **kwargs)
  File "/Users/Insolia/Code/Python/bank_2.0/bank_app/bank_api/views.py", line 42, in get_session
    request_data = json.loads(str(request.body, 'utf-8'))
  File "/Library/Frameworks/Python.framework/Versions/3.6/lib/python3.6/json/__init__.py", line 354, in loads
    return _default_decoder.decode(s)
  File "/Library/Frameworks/Python.framework/Versions/3.6/lib/python3.6/json/decoder.py", line 339, in decode
    obj, end = self.raw_decode(s, idx=_w(s, 0).end())
  File "/Library/Frameworks/Python.framework/Versions/3.6/lib/python3.6/json/decoder.py", line 357, in raw_decode
    raise JSONDecodeError("Expecting value", s, err.value) from None
json.decoder.JSONDecodeError: Expecting value: line 1 column 1 (char 0)
ERROR 2017-08-15 13:22:34,552 "POST /bank_api/auth/ HTTP/1.1" 500 85692
