ERROR 2017-09-15 21:52:00,840 Internal Server Error: /bank/
Traceback (most recent call last):
  File "/Users/Insolia/Code/Python/bank_2.0/env/bank_2.0_venv/lib/python3.6/site-packages/django/core/handlers/exception.py", line 41, in inner
    response = get_response(request)
  File "/Users/Insolia/Code/Python/bank_2.0/env/bank_2.0_venv/lib/python3.6/site-packages/django/core/handlers/base.py", line 249, in _legacy_get_response
    response = self._get_response(request)
  File "/Users/Insolia/Code/Python/bank_2.0/env/bank_2.0_venv/lib/python3.6/site-packages/django/core/handlers/base.py", line 187, in _get_response
    response = self.process_exception_by_middleware(e, request)
  File "/Users/Insolia/Code/Python/bank_2.0/env/bank_2.0_venv/lib/python3.6/site-packages/django/core/handlers/base.py", line 185, in _get_response
    response = wrapped_callback(request, *callback_args, **callback_kwargs)
  File "/Users/Insolia/Code/Python/bank_2.0/env/bank_2.0_venv/lib/python3.6/site-packages/django/contrib/auth/decorators.py", line 23, in _wrapped_view
    return view_func(request, *args, **kwargs)
  File "/Users/Insolia/Code/Python/bank_2.0/bank_app/bank/views.py", line 26, in index
    log.info("index page request from {}".format(request.user.account.long_name()))
  File "/Users/Insolia/Code/Python/bank_2.0/env/bank_2.0_venv/lib/python3.6/site-packages/django/utils/functional.py", line 239, in inner
    return func(self._wrapped, *args)
  File "/Users/Insolia/Code/Python/bank_2.0/env/bank_2.0_venv/lib/python3.6/site-packages/django/db/models/fields/related_descriptors.py", line 406, in __get__
    self.related.get_accessor_name()
django.db.models.fields.related_descriptors.RelatedObjectDoesNotExist: User has no account.
ERROR 2017-09-15 21:52:01,001 "GET /bank/ HTTP/1.1" 500 81204
ERROR 2017-09-15 22:22:22,421 Internal Server Error: /bank_api/money/
Traceback (most recent call last):
  File "/Users/Insolia/Code/Python/bank_2.0/env/bank_2.0_venv/lib/python3.6/site-packages/django/core/handlers/exception.py", line 41, in inner
    response = get_response(request)
  File "/Users/Insolia/Code/Python/bank_2.0/env/bank_2.0_venv/lib/python3.6/site-packages/django/core/handlers/base.py", line 249, in _legacy_get_response
    response = self._get_response(request)
  File "/Users/Insolia/Code/Python/bank_2.0/env/bank_2.0_venv/lib/python3.6/site-packages/django/core/handlers/base.py", line 187, in _get_response
    response = self.process_exception_by_middleware(e, request)
  File "/Users/Insolia/Code/Python/bank_2.0/env/bank_2.0_venv/lib/python3.6/site-packages/django/core/handlers/base.py", line 185, in _get_response
    response = wrapped_callback(request, *callback_args, **callback_kwargs)
  File "/Users/Insolia/Code/Python/bank_2.0/env/bank_2.0_venv/lib/python3.6/site-packages/django/views/decorators/csrf.py", line 58, in wrapped_view
    return view_func(*args, **kwargs)
  File "/Users/Insolia/Code/Python/bank_2.0/bank_app/bank_api/views.py", line 68, in get_students_money
    writer.writerow(Money.objects.all().first().full_info_headers_as_list())
  File "/Users/Insolia/Code/Python/bank_2.0/bank_app/bank/models/Money.py", line 81, in full_info_headers_as_list
    ['receiver_' + x for x in self.receiver.account.full_info_headers_as_list()] + \
  File "/Users/Insolia/Code/Python/bank_2.0/bank_app/bank/models/AtomicTransactionType.py", line 23, in full_info_headers_as_list
    ] + super(self).full_info_headers_as_list()
TypeError: super() argument 1 must be type, not MoneyType
ERROR 2017-09-15 22:22:22,514 "GET /bank_api/money/ HTTP/1.1" 500 78646
ERROR 2017-09-15 22:25:53,577 Internal Server Error: /bank_api/money/
Traceback (most recent call last):
  File "/Users/Insolia/Code/Python/bank_2.0/env/bank_2.0_venv/lib/python3.6/site-packages/django/core/handlers/exception.py", line 41, in inner
    response = get_response(request)
  File "/Users/Insolia/Code/Python/bank_2.0/env/bank_2.0_venv/lib/python3.6/site-packages/django/core/handlers/base.py", line 249, in _legacy_get_response
    response = self._get_response(request)
  File "/Users/Insolia/Code/Python/bank_2.0/env/bank_2.0_venv/lib/python3.6/site-packages/django/core/handlers/base.py", line 187, in _get_response
    response = self.process_exception_by_middleware(e, request)
  File "/Users/Insolia/Code/Python/bank_2.0/env/bank_2.0_venv/lib/python3.6/site-packages/django/core/handlers/base.py", line 185, in _get_response
    response = wrapped_callback(request, *callback_args, **callback_kwargs)
  File "/Users/Insolia/Code/Python/bank_2.0/env/bank_2.0_venv/lib/python3.6/site-packages/django/views/decorators/csrf.py", line 58, in wrapped_view
    return view_func(*args, **kwargs)
  File "/Users/Insolia/Code/Python/bank_2.0/bank_app/bank_api/views.py", line 68, in get_students_money
    writer.writerow(Money.objects.all().first().full_info_headers_as_list())
  File "/Users/Insolia/Code/Python/bank_2.0/bank_app/bank/models/Money.py", line 81, in full_info_headers_as_list
    ['receiver_' + x for x in self.receiver.account.full_info_headers_as_list()] + \
  File "/Users/Insolia/Code/Python/bank_2.0/bank_app/bank/models/AtomicTransactionType.py", line 23, in full_info_headers_as_list
    ] + super(self).full_info_headers_as_list()
TypeError: super() argument 1 must be type, not MoneyType
ERROR 2017-09-15 22:25:53,688 "GET /bank_api/money/ HTTP/1.1" 500 78647
ERROR 2017-09-15 22:26:18,720 Internal Server Error: /bank_api/money/
Traceback (most recent call last):
  File "/Users/Insolia/Code/Python/bank_2.0/env/bank_2.0_venv/lib/python3.6/site-packages/django/core/handlers/exception.py", line 41, in inner
    response = get_response(request)
  File "/Users/Insolia/Code/Python/bank_2.0/env/bank_2.0_venv/lib/python3.6/site-packages/django/core/handlers/base.py", line 249, in _legacy_get_response
    response = self._get_response(request)
  File "/Users/Insolia/Code/Python/bank_2.0/env/bank_2.0_venv/lib/python3.6/site-packages/django/core/handlers/base.py", line 187, in _get_response
    response = self.process_exception_by_middleware(e, request)
  File "/Users/Insolia/Code/Python/bank_2.0/env/bank_2.0_venv/lib/python3.6/site-packages/django/core/handlers/base.py", line 185, in _get_response
    response = wrapped_callback(request, *callback_args, **callback_kwargs)
  File "/Users/Insolia/Code/Python/bank_2.0/env/bank_2.0_venv/lib/python3.6/site-packages/django/views/decorators/csrf.py", line 58, in wrapped_view
    return view_func(*args, **kwargs)
  File "/Users/Insolia/Code/Python/bank_2.0/bank_app/bank_api/views.py", line 68, in get_students_money
    writer.writerow(Money.objects.all().first().full_info_headers_as_list())
  File "/Users/Insolia/Code/Python/bank_2.0/bank_app/bank/models/Money.py", line 81, in full_info_headers_as_list
    ['receiver_' + x for x in self.receiver.account.full_info_headers_as_list()] + \
  File "/Users/Insolia/Code/Python/bank_2.0/bank_app/bank/models/AtomicTransactionType.py", line 23, in full_info_headers_as_list
    ] + super(self.__class__).full_info_headers_as_list()
TypeError: super() argument 1 must be type, not MoneyType
ERROR 2017-09-15 22:26:18,794 "GET /bank_api/money/ HTTP/1.1" 500 78677
ERROR 2017-09-15 22:27:55,296 Internal Server Error: /bank_api/money/
Traceback (most recent call last):
  File "/Users/Insolia/Code/Python/bank_2.0/env/bank_2.0_venv/lib/python3.6/site-packages/django/core/handlers/exception.py", line 41, in inner
    response = get_response(request)
  File "/Users/Insolia/Code/Python/bank_2.0/env/bank_2.0_venv/lib/python3.6/site-packages/django/core/handlers/base.py", line 249, in _legacy_get_response
    response = self._get_response(request)
  File "/Users/Insolia/Code/Python/bank_2.0/env/bank_2.0_venv/lib/python3.6/site-packages/django/core/handlers/base.py", line 187, in _get_response
    response = self.process_exception_by_middleware(e, request)
  File "/Users/Insolia/Code/Python/bank_2.0/env/bank_2.0_venv/lib/python3.6/site-packages/django/core/handlers/base.py", line 185, in _get_response
    response = wrapped_callback(request, *callback_args, **callback_kwargs)
  File "/Users/Insolia/Code/Python/bank_2.0/env/bank_2.0_venv/lib/python3.6/site-packages/django/views/decorators/csrf.py", line 58, in wrapped_view
    return view_func(*args, **kwargs)
  File "/Users/Insolia/Code/Python/bank_2.0/bank_app/bank_api/views.py", line 68, in get_students_money
    writer.writerow(Money.objects.all().first().full_info_headers_as_list())
  File "/Users/Insolia/Code/Python/bank_2.0/bank_app/bank/models/Money.py", line 81, in full_info_headers_as_list
    ['receiver_' + x for x in self.receiver.account.full_info_headers_as_list()] + \
  File "/Users/Insolia/Code/Python/bank_2.0/bank_app/bank/models/AtomicTransactionType.py", line 23, in full_info_headers_as_list
    ] + super(self.__class__).full_info_headers_as_list()
AttributeError: 'super' object has no attribute 'full_info_headers_as_list'
ERROR 2017-09-15 22:27:55,382 "GET /bank_api/money/ HTTP/1.1" 500 78832
ERROR 2017-09-15 22:28:11,175 Internal Server Error: /bank_api/money/
Traceback (most recent call last):
  File "/Users/Insolia/Code/Python/bank_2.0/env/bank_2.0_venv/lib/python3.6/site-packages/django/core/handlers/exception.py", line 41, in inner
    response = get_response(request)
  File "/Users/Insolia/Code/Python/bank_2.0/env/bank_2.0_venv/lib/python3.6/site-packages/django/core/handlers/base.py", line 249, in _legacy_get_response
    response = self._get_response(request)
  File "/Users/Insolia/Code/Python/bank_2.0/env/bank_2.0_venv/lib/python3.6/site-packages/django/core/handlers/base.py", line 187, in _get_response
    response = self.process_exception_by_middleware(e, request)
  File "/Users/Insolia/Code/Python/bank_2.0/env/bank_2.0_venv/lib/python3.6/site-packages/django/core/handlers/base.py", line 185, in _get_response
    response = wrapped_callback(request, *callback_args, **callback_kwargs)
  File "/Users/Insolia/Code/Python/bank_2.0/env/bank_2.0_venv/lib/python3.6/site-packages/django/views/decorators/csrf.py", line 58, in wrapped_view
    return view_func(*args, **kwargs)
  File "/Users/Insolia/Code/Python/bank_2.0/bank_app/bank_api/views.py", line 68, in get_students_money
    writer.writerow(Money.objects.all().first().full_info_headers_as_list())
  File "/Users/Insolia/Code/Python/bank_2.0/bank_app/bank/models/Money.py", line 81, in full_info_headers_as_list
    ['receiver_' + x for x in self.receiver.account.full_info_headers_as_list()] + \
  File "/Users/Insolia/Code/Python/bank_2.0/bank_app/bank/models/AtomicTransactionType.py", line 23, in full_info_headers_as_list
    ] + super(AtomicTransactionType).full_info_headers_as_list()
AttributeError: 'super' object has no attribute 'full_info_headers_as_list'
ERROR 2017-09-15 22:28:11,274 "GET /bank_api/money/ HTTP/1.1" 500 78846
ERROR 2017-09-15 22:29:11,997 Internal Server Error: /bank_api/money/
Traceback (most recent call last):
  File "/Users/Insolia/Code/Python/bank_2.0/env/bank_2.0_venv/lib/python3.6/site-packages/django/core/handlers/exception.py", line 41, in inner
    response = get_response(request)
  File "/Users/Insolia/Code/Python/bank_2.0/env/bank_2.0_venv/lib/python3.6/site-packages/django/core/handlers/base.py", line 249, in _legacy_get_response
    response = self._get_response(request)
  File "/Users/Insolia/Code/Python/bank_2.0/env/bank_2.0_venv/lib/python3.6/site-packages/django/core/handlers/base.py", line 187, in _get_response
    response = self.process_exception_by_middleware(e, request)
  File "/Users/Insolia/Code/Python/bank_2.0/env/bank_2.0_venv/lib/python3.6/site-packages/django/core/handlers/base.py", line 185, in _get_response
    response = wrapped_callback(request, *callback_args, **callback_kwargs)
  File "/Users/Insolia/Code/Python/bank_2.0/env/bank_2.0_venv/lib/python3.6/site-packages/django/views/decorators/csrf.py", line 58, in wrapped_view
    return view_func(*args, **kwargs)
  File "/Users/Insolia/Code/Python/bank_2.0/bank_app/bank_api/views.py", line 68, in get_students_money
    writer.writerow(Money.objects.all().first().full_info_headers_as_list())
  File "/Users/Insolia/Code/Python/bank_2.0/bank_app/bank/models/Money.py", line 81, in full_info_headers_as_list
    ['receiver_' + x for x in self.receiver.account.full_info_headers_as_list()] + \
AttributeError: 'super' object has no attribute 'full_info_headers_as_list'
ERROR 2017-09-15 22:29:12,075 "GET /bank_api/money/ HTTP/1.1" 500 75358
ERROR 2017-09-15 22:29:54,794 Internal Server Error: /bank_api/money/
Traceback (most recent call last):
  File "/Users/Insolia/Code/Python/bank_2.0/env/bank_2.0_venv/lib/python3.6/site-packages/django/core/handlers/exception.py", line 41, in inner
    response = get_response(request)
  File "/Users/Insolia/Code/Python/bank_2.0/env/bank_2.0_venv/lib/python3.6/site-packages/django/core/handlers/base.py", line 249, in _legacy_get_response
    response = self._get_response(request)
  File "/Users/Insolia/Code/Python/bank_2.0/env/bank_2.0_venv/lib/python3.6/site-packages/django/core/handlers/base.py", line 187, in _get_response
    response = self.process_exception_by_middleware(e, request)
  File "/Users/Insolia/Code/Python/bank_2.0/env/bank_2.0_venv/lib/python3.6/site-packages/django/core/handlers/base.py", line 185, in _get_response
    response = wrapped_callback(request, *callback_args, **callback_kwargs)
  File "/Users/Insolia/Code/Python/bank_2.0/env/bank_2.0_venv/lib/python3.6/site-packages/django/views/decorators/csrf.py", line 58, in wrapped_view
    return view_func(*args, **kwargs)
  File "/Users/Insolia/Code/Python/bank_2.0/bank_app/bank_api/views.py", line 68, in get_students_money
    writer.writerow(Money.objects.all().first().full_info_headers_as_list())
  File "/Users/Insolia/Code/Python/bank_2.0/bank_app/bank/models/Money.py", line 81, in full_info_headers_as_list
    ['receiver_' + x for x in self.receiver.account.full_info_headers_as_list()] + \
AttributeError: 'super' object has no attribute 'full_info_headers_as_list'
ERROR 2017-09-15 22:29:54,867 "GET /bank_api/money/ HTTP/1.1" 500 75353
ERROR 2017-09-15 22:32:24,636 Internal Server Error: /bank_api/money/
Traceback (most recent call last):
  File "/Users/Insolia/Code/Python/bank_2.0/env/bank_2.0_venv/lib/python3.6/site-packages/django/core/handlers/exception.py", line 41, in inner
    response = get_response(request)
  File "/Users/Insolia/Code/Python/bank_2.0/env/bank_2.0_venv/lib/python3.6/site-packages/django/core/handlers/base.py", line 249, in _legacy_get_response
    response = self._get_response(request)
  File "/Users/Insolia/Code/Python/bank_2.0/env/bank_2.0_venv/lib/python3.6/site-packages/django/core/handlers/base.py", line 187, in _get_response
    response = self.process_exception_by_middleware(e, request)
  File "/Users/Insolia/Code/Python/bank_2.0/env/bank_2.0_venv/lib/python3.6/site-packages/django/core/handlers/base.py", line 185, in _get_response
    response = wrapped_callback(request, *callback_args, **callback_kwargs)
  File "/Users/Insolia/Code/Python/bank_2.0/env/bank_2.0_venv/lib/python3.6/site-packages/django/views/decorators/csrf.py", line 58, in wrapped_view
    return view_func(*args, **kwargs)
  File "/Users/Insolia/Code/Python/bank_2.0/bank_app/bank_api/views.py", line 68, in get_students_money
    writer.writerow(Money.objects.all().first().full_info_headers_as_list())
  File "/Users/Insolia/Code/Python/bank_2.0/bank_app/bank/models/Money.py", line 81, in full_info_headers_as_list
    ['receiver_' + x for x in self.receiver.account.full_info_headers_as_list()] + \
TypeError: super() argument 1 must be type, not Money
ERROR 2017-09-15 22:32:24,722 "GET /bank_api/money/ HTTP/1.1" 500 75193
ERROR 2017-09-15 22:32:49,191 Internal Server Error: /bank_api/money/
Traceback (most recent call last):
  File "/Users/Insolia/Code/Python/bank_2.0/env/bank_2.0_venv/lib/python3.6/site-packages/django/core/handlers/exception.py", line 41, in inner
    response = get_response(request)
  File "/Users/Insolia/Code/Python/bank_2.0/env/bank_2.0_venv/lib/python3.6/site-packages/django/core/handlers/base.py", line 249, in _legacy_get_response
    response = self._get_response(request)
  File "/Users/Insolia/Code/Python/bank_2.0/env/bank_2.0_venv/lib/python3.6/site-packages/django/core/handlers/base.py", line 187, in _get_response
    response = self.process_exception_by_middleware(e, request)
  File "/Users/Insolia/Code/Python/bank_2.0/env/bank_2.0_venv/lib/python3.6/site-packages/django/core/handlers/base.py", line 185, in _get_response
    response = wrapped_callback(request, *callback_args, **callback_kwargs)
  File "/Users/Insolia/Code/Python/bank_2.0/env/bank_2.0_venv/lib/python3.6/site-packages/django/views/decorators/csrf.py", line 58, in wrapped_view
    return view_func(*args, **kwargs)
  File "/Users/Insolia/Code/Python/bank_2.0/bank_app/bank_api/views.py", line 68, in get_students_money
    writer.writerow(Money.objects.all().first().full_info_headers_as_list())
  File "/Users/Insolia/Code/Python/bank_2.0/bank_app/bank/models/Money.py", line 81, in full_info_headers_as_list
    ['receiver_' + x for x in self.receiver.account.full_info_headers_as_list()] + \
TypeError: super() argument 1 must be type, not Money
ERROR 2017-09-15 22:32:49,248 "GET /bank_api/money/ HTTP/1.1" 500 75199
ERROR 2018-06-11 16:40:31,699 Internal Server Error: /bank/add_transaction/seminar/
Traceback (most recent call last):
  File "/Users/Insolia/Code/Python/bank_2.0/env/bank_2.0_venv/lib/python3.6/site-packages/django/core/handlers/exception.py", line 41, in inner
    response = get_response(request)
  File "/Users/Insolia/Code/Python/bank_2.0/env/bank_2.0_venv/lib/python3.6/site-packages/django/core/handlers/base.py", line 249, in _legacy_get_response
    response = self._get_response(request)
  File "/Users/Insolia/Code/Python/bank_2.0/env/bank_2.0_venv/lib/python3.6/site-packages/django/core/handlers/base.py", line 187, in _get_response
    response = self.process_exception_by_middleware(e, request)
  File "/Users/Insolia/Code/Python/bank_2.0/env/bank_2.0_venv/lib/python3.6/site-packages/django/core/handlers/base.py", line 185, in _get_response
    response = wrapped_callback(request, *callback_args, **callback_kwargs)
  File "/Users/Insolia/Code/Python/bank_2.0/env/bank_2.0_venv/lib/python3.6/site-packages/django/contrib/auth/decorators.py", line 23, in _wrapped_view
    return view_func(request, *args, **kwargs)
  File "/Users/Insolia/Code/Python/bank_2.0/bank_app/bank/views.py", line 65, in add_transaction
    if formset.is_valid():
  File "/Users/Insolia/Code/Python/bank_2.0/env/bank_2.0_venv/lib/python3.6/site-packages/django/forms/formsets.py", line 321, in is_valid
    self.errors
  File "/Users/Insolia/Code/Python/bank_2.0/env/bank_2.0_venv/lib/python3.6/site-packages/django/forms/formsets.py", line 295, in errors
    self.full_clean()
  File "/Users/Insolia/Code/Python/bank_2.0/env/bank_2.0_venv/lib/python3.6/site-packages/django/forms/formsets.py", line 366, in full_clean
    self.clean()
  File "/Users/Insolia/Code/Python/bank_2.0/bank_app/bank/forms.py", line 281, in clean
    self.add_error('block', "Докладчик уже занимался чем-то в этот блок. Может быть вы перепутали докладчика или блок? \
AttributeError: 'SeminarKernelFormFormSet' object has no attribute 'add_error'
ERROR 2018-06-11 16:40:32,182 "POST /bank/add_transaction/seminar/ HTTP/1.1" 500 347398
ERROR 2018-06-11 16:43:06,705 Internal Server Error: /bank/add_transaction/seminar/
Traceback (most recent call last):
  File "/Users/Insolia/Code/Python/bank_2.0/env/bank_2.0_venv/lib/python3.6/site-packages/django/core/handlers/exception.py", line 41, in inner
    response = get_response(request)
  File "/Users/Insolia/Code/Python/bank_2.0/env/bank_2.0_venv/lib/python3.6/site-packages/django/core/handlers/base.py", line 249, in _legacy_get_response
    response = self._get_response(request)
  File "/Users/Insolia/Code/Python/bank_2.0/env/bank_2.0_venv/lib/python3.6/site-packages/django/core/handlers/base.py", line 187, in _get_response
    response = self.process_exception_by_middleware(e, request)
  File "/Users/Insolia/Code/Python/bank_2.0/env/bank_2.0_venv/lib/python3.6/site-packages/django/core/handlers/base.py", line 185, in _get_response
    response = wrapped_callback(request, *callback_args, **callback_kwargs)
  File "/Users/Insolia/Code/Python/bank_2.0/env/bank_2.0_venv/lib/python3.6/site-packages/django/contrib/auth/decorators.py", line 23, in _wrapped_view
    return view_func(request, *args, **kwargs)
  File "/Users/Insolia/Code/Python/bank_2.0/bank_app/bank/views.py", line 65, in add_transaction
    if formset.is_valid():
  File "/Users/Insolia/Code/Python/bank_2.0/env/bank_2.0_venv/lib/python3.6/site-packages/django/forms/formsets.py", line 321, in is_valid
    self.errors
  File "/Users/Insolia/Code/Python/bank_2.0/env/bank_2.0_venv/lib/python3.6/site-packages/django/forms/formsets.py", line 295, in errors
    self.full_clean()
  File "/Users/Insolia/Code/Python/bank_2.0/env/bank_2.0_venv/lib/python3.6/site-packages/django/forms/formsets.py", line 366, in full_clean
    self.clean()
  File "/Users/Insolia/Code/Python/bank_2.0/bank_app/bank/forms.py", line 282, in clean
    test_attendance.delete()
  File "/Users/Insolia/Code/Python/bank_2.0/env/bank_2.0_venv/lib/python3.6/site-packages/django/db/models/base.py", line 967, in delete
    (self._meta.object_name, self._meta.pk.attname)
AssertionError: Attendance object can't be deleted because its id attribute is set to None.
ERROR 2018-06-11 16:43:07,070 "POST /bank/add_transaction/seminar/ HTTP/1.1" 500 350864
