ERROR 2017-09-15 21:52:00,840 Internal Server Error: /bank/
Traceback (most recent call last):
  File "/Users/Insolia/Code/Python/bank_2.0/env/bank_2.0_venv/lib/python3.6/site-packages/django/core/handlers/exception.py", line 41, in inner
    response = get_response(request)
  File "/Users/Insolia/Code/Python/bank_2.0/env/bank_2.0_venv/lib/python3.6/site-packages/django/core/handlers/base.py", line 249, in _legacy_get_response
    response = self._get_response(request)
  File "/Users/Insolia/Code/Python/bank_2.0/env/bank_2.0_venv/lib/python3.6/site-packages/django/core/handlers/base.py", line 187, in _get_response
    response = self.process_exception_by_middleware(e, request)
  File "/Users/Insolia/Code/Python/bank_2.0/env/bank_2.0_venv/lib/python3.6/site-packages/django/core/handlers/base.py", line 185, in _get_response
    response = wrapped_callback(request, *callback_args, **callback_kwargs)
  File "/Users/Insolia/Code/Python/bank_2.0/env/bank_2.0_venv/lib/python3.6/site-packages/django/contrib/auth/decorators.py", line 23, in _wrapped_view
    return view_func(request, *args, **kwargs)
  File "/Users/Insolia/Code/Python/bank_2.0/bank_app/bank/views.py", line 26, in index
    log.info("index page request from {}".format(request.user.account.long_name()))
  File "/Users/Insolia/Code/Python/bank_2.0/env/bank_2.0_venv/lib/python3.6/site-packages/django/utils/functional.py", line 239, in inner
    return func(self._wrapped, *args)
  File "/Users/Insolia/Code/Python/bank_2.0/env/bank_2.0_venv/lib/python3.6/site-packages/django/db/models/fields/related_descriptors.py", line 406, in __get__
    self.related.get_accessor_name()
django.db.models.fields.related_descriptors.RelatedObjectDoesNotExist: User has no account.
ERROR 2017-09-15 21:52:01,001 "GET /bank/ HTTP/1.1" 500 81204
ERROR 2017-09-15 22:22:22,421 Internal Server Error: /bank_api/money/
Traceback (most recent call last):
  File "/Users/Insolia/Code/Python/bank_2.0/env/bank_2.0_venv/lib/python3.6/site-packages/django/core/handlers/exception.py", line 41, in inner
    response = get_response(request)
  File "/Users/Insolia/Code/Python/bank_2.0/env/bank_2.0_venv/lib/python3.6/site-packages/django/core/handlers/base.py", line 249, in _legacy_get_response
    response = self._get_response(request)
  File "/Users/Insolia/Code/Python/bank_2.0/env/bank_2.0_venv/lib/python3.6/site-packages/django/core/handlers/base.py", line 187, in _get_response
    response = self.process_exception_by_middleware(e, request)
  File "/Users/Insolia/Code/Python/bank_2.0/env/bank_2.0_venv/lib/python3.6/site-packages/django/core/handlers/base.py", line 185, in _get_response
    response = wrapped_callback(request, *callback_args, **callback_kwargs)
  File "/Users/Insolia/Code/Python/bank_2.0/env/bank_2.0_venv/lib/python3.6/site-packages/django/views/decorators/csrf.py", line 58, in wrapped_view
    return view_func(*args, **kwargs)
  File "/Users/Insolia/Code/Python/bank_2.0/bank_app/bank_api/views.py", line 68, in get_students_money
    writer.writerow(Money.objects.all().first().full_info_headers_as_list())
  File "/Users/Insolia/Code/Python/bank_2.0/bank_app/bank/models/Money.py", line 81, in full_info_headers_as_list
    ['receiver_' + x for x in self.receiver.account.full_info_headers_as_list()] + \
  File "/Users/Insolia/Code/Python/bank_2.0/bank_app/bank/models/AtomicTransactionType.py", line 23, in full_info_headers_as_list
    ] + super(self).full_info_headers_as_list()
TypeError: super() argument 1 must be type, not MoneyType
ERROR 2017-09-15 22:22:22,514 "GET /bank_api/money/ HTTP/1.1" 500 78646
ERROR 2017-09-15 22:25:53,577 Internal Server Error: /bank_api/money/
Traceback (most recent call last):
  File "/Users/Insolia/Code/Python/bank_2.0/env/bank_2.0_venv/lib/python3.6/site-packages/django/core/handlers/exception.py", line 41, in inner
    response = get_response(request)
  File "/Users/Insolia/Code/Python/bank_2.0/env/bank_2.0_venv/lib/python3.6/site-packages/django/core/handlers/base.py", line 249, in _legacy_get_response
    response = self._get_response(request)
  File "/Users/Insolia/Code/Python/bank_2.0/env/bank_2.0_venv/lib/python3.6/site-packages/django/core/handlers/base.py", line 187, in _get_response
    response = self.process_exception_by_middleware(e, request)
  File "/Users/Insolia/Code/Python/bank_2.0/env/bank_2.0_venv/lib/python3.6/site-packages/django/core/handlers/base.py", line 185, in _get_response
    response = wrapped_callback(request, *callback_args, **callback_kwargs)
  File "/Users/Insolia/Code/Python/bank_2.0/env/bank_2.0_venv/lib/python3.6/site-packages/django/views/decorators/csrf.py", line 58, in wrapped_view
    return view_func(*args, **kwargs)
  File "/Users/Insolia/Code/Python/bank_2.0/bank_app/bank_api/views.py", line 68, in get_students_money
    writer.writerow(Money.objects.all().first().full_info_headers_as_list())
  File "/Users/Insolia/Code/Python/bank_2.0/bank_app/bank/models/Money.py", line 81, in full_info_headers_as_list
    ['receiver_' + x for x in self.receiver.account.full_info_headers_as_list()] + \
  File "/Users/Insolia/Code/Python/bank_2.0/bank_app/bank/models/AtomicTransactionType.py", line 23, in full_info_headers_as_list
    ] + super(self).full_info_headers_as_list()
TypeError: super() argument 1 must be type, not MoneyType
ERROR 2017-09-15 22:25:53,688 "GET /bank_api/money/ HTTP/1.1" 500 78647
ERROR 2017-09-15 22:26:18,720 Internal Server Error: /bank_api/money/
Traceback (most recent call last):
  File "/Users/Insolia/Code/Python/bank_2.0/env/bank_2.0_venv/lib/python3.6/site-packages/django/core/handlers/exception.py", line 41, in inner
    response = get_response(request)
  File "/Users/Insolia/Code/Python/bank_2.0/env/bank_2.0_venv/lib/python3.6/site-packages/django/core/handlers/base.py", line 249, in _legacy_get_response
    response = self._get_response(request)
  File "/Users/Insolia/Code/Python/bank_2.0/env/bank_2.0_venv/lib/python3.6/site-packages/django/core/handlers/base.py", line 187, in _get_response
    response = self.process_exception_by_middleware(e, request)
  File "/Users/Insolia/Code/Python/bank_2.0/env/bank_2.0_venv/lib/python3.6/site-packages/django/core/handlers/base.py", line 185, in _get_response
    response = wrapped_callback(request, *callback_args, **callback_kwargs)
  File "/Users/Insolia/Code/Python/bank_2.0/env/bank_2.0_venv/lib/python3.6/site-packages/django/views/decorators/csrf.py", line 58, in wrapped_view
    return view_func(*args, **kwargs)
  File "/Users/Insolia/Code/Python/bank_2.0/bank_app/bank_api/views.py", line 68, in get_students_money
    writer.writerow(Money.objects.all().first().full_info_headers_as_list())
  File "/Users/Insolia/Code/Python/bank_2.0/bank_app/bank/models/Money.py", line 81, in full_info_headers_as_list
    ['receiver_' + x for x in self.receiver.account.full_info_headers_as_list()] + \
  File "/Users/Insolia/Code/Python/bank_2.0/bank_app/bank/models/AtomicTransactionType.py", line 23, in full_info_headers_as_list
    ] + super(self.__class__).full_info_headers_as_list()
TypeError: super() argument 1 must be type, not MoneyType
ERROR 2017-09-15 22:26:18,794 "GET /bank_api/money/ HTTP/1.1" 500 78677
ERROR 2017-09-15 22:27:55,296 Internal Server Error: /bank_api/money/
Traceback (most recent call last):
  File "/Users/Insolia/Code/Python/bank_2.0/env/bank_2.0_venv/lib/python3.6/site-packages/django/core/handlers/exception.py", line 41, in inner
    response = get_response(request)
  File "/Users/Insolia/Code/Python/bank_2.0/env/bank_2.0_venv/lib/python3.6/site-packages/django/core/handlers/base.py", line 249, in _legacy_get_response
    response = self._get_response(request)
  File "/Users/Insolia/Code/Python/bank_2.0/env/bank_2.0_venv/lib/python3.6/site-packages/django/core/handlers/base.py", line 187, in _get_response
    response = self.process_exception_by_middleware(e, request)
  File "/Users/Insolia/Code/Python/bank_2.0/env/bank_2.0_venv/lib/python3.6/site-packages/django/core/handlers/base.py", line 185, in _get_response
    response = wrapped_callback(request, *callback_args, **callback_kwargs)
  File "/Users/Insolia/Code/Python/bank_2.0/env/bank_2.0_venv/lib/python3.6/site-packages/django/views/decorators/csrf.py", line 58, in wrapped_view
    return view_func(*args, **kwargs)
  File "/Users/Insolia/Code/Python/bank_2.0/bank_app/bank_api/views.py", line 68, in get_students_money
    writer.writerow(Money.objects.all().first().full_info_headers_as_list())
  File "/Users/Insolia/Code/Python/bank_2.0/bank_app/bank/models/Money.py", line 81, in full_info_headers_as_list
    ['receiver_' + x for x in self.receiver.account.full_info_headers_as_list()] + \
  File "/Users/Insolia/Code/Python/bank_2.0/bank_app/bank/models/AtomicTransactionType.py", line 23, in full_info_headers_as_list
    ] + super(self.__class__).full_info_headers_as_list()
AttributeError: 'super' object has no attribute 'full_info_headers_as_list'
ERROR 2017-09-15 22:27:55,382 "GET /bank_api/money/ HTTP/1.1" 500 78832
ERROR 2017-09-15 22:28:11,175 Internal Server Error: /bank_api/money/
Traceback (most recent call last):
  File "/Users/Insolia/Code/Python/bank_2.0/env/bank_2.0_venv/lib/python3.6/site-packages/django/core/handlers/exception.py", line 41, in inner
    response = get_response(request)
  File "/Users/Insolia/Code/Python/bank_2.0/env/bank_2.0_venv/lib/python3.6/site-packages/django/core/handlers/base.py", line 249, in _legacy_get_response
    response = self._get_response(request)
  File "/Users/Insolia/Code/Python/bank_2.0/env/bank_2.0_venv/lib/python3.6/site-packages/django/core/handlers/base.py", line 187, in _get_response
    response = self.process_exception_by_middleware(e, request)
  File "/Users/Insolia/Code/Python/bank_2.0/env/bank_2.0_venv/lib/python3.6/site-packages/django/core/handlers/base.py", line 185, in _get_response
    response = wrapped_callback(request, *callback_args, **callback_kwargs)
  File "/Users/Insolia/Code/Python/bank_2.0/env/bank_2.0_venv/lib/python3.6/site-packages/django/views/decorators/csrf.py", line 58, in wrapped_view
    return view_func(*args, **kwargs)
  File "/Users/Insolia/Code/Python/bank_2.0/bank_app/bank_api/views.py", line 68, in get_students_money
    writer.writerow(Money.objects.all().first().full_info_headers_as_list())
  File "/Users/Insolia/Code/Python/bank_2.0/bank_app/bank/models/Money.py", line 81, in full_info_headers_as_list
    ['receiver_' + x for x in self.receiver.account.full_info_headers_as_list()] + \
  File "/Users/Insolia/Code/Python/bank_2.0/bank_app/bank/models/AtomicTransactionType.py", line 23, in full_info_headers_as_list
    ] + super(AtomicTransactionType).full_info_headers_as_list()
AttributeError: 'super' object has no attribute 'full_info_headers_as_list'
ERROR 2017-09-15 22:28:11,274 "GET /bank_api/money/ HTTP/1.1" 500 78846
ERROR 2017-09-15 22:29:11,997 Internal Server Error: /bank_api/money/
Traceback (most recent call last):
  File "/Users/Insolia/Code/Python/bank_2.0/env/bank_2.0_venv/lib/python3.6/site-packages/django/core/handlers/exception.py", line 41, in inner
    response = get_response(request)
  File "/Users/Insolia/Code/Python/bank_2.0/env/bank_2.0_venv/lib/python3.6/site-packages/django/core/handlers/base.py", line 249, in _legacy_get_response
    response = self._get_response(request)
  File "/Users/Insolia/Code/Python/bank_2.0/env/bank_2.0_venv/lib/python3.6/site-packages/django/core/handlers/base.py", line 187, in _get_response
    response = self.process_exception_by_middleware(e, request)
  File "/Users/Insolia/Code/Python/bank_2.0/env/bank_2.0_venv/lib/python3.6/site-packages/django/core/handlers/base.py", line 185, in _get_response
    response = wrapped_callback(request, *callback_args, **callback_kwargs)
  File "/Users/Insolia/Code/Python/bank_2.0/env/bank_2.0_venv/lib/python3.6/site-packages/django/views/decorators/csrf.py", line 58, in wrapped_view
    return view_func(*args, **kwargs)
  File "/Users/Insolia/Code/Python/bank_2.0/bank_app/bank_api/views.py", line 68, in get_students_money
    writer.writerow(Money.objects.all().first().full_info_headers_as_list())
  File "/Users/Insolia/Code/Python/bank_2.0/bank_app/bank/models/Money.py", line 81, in full_info_headers_as_list
    ['receiver_' + x for x in self.receiver.account.full_info_headers_as_list()] + \
AttributeError: 'super' object has no attribute 'full_info_headers_as_list'
ERROR 2017-09-15 22:29:12,075 "GET /bank_api/money/ HTTP/1.1" 500 75358
ERROR 2017-09-15 22:29:54,794 Internal Server Error: /bank_api/money/
Traceback (most recent call last):
  File "/Users/Insolia/Code/Python/bank_2.0/env/bank_2.0_venv/lib/python3.6/site-packages/django/core/handlers/exception.py", line 41, in inner
    response = get_response(request)
  File "/Users/Insolia/Code/Python/bank_2.0/env/bank_2.0_venv/lib/python3.6/site-packages/django/core/handlers/base.py", line 249, in _legacy_get_response
    response = self._get_response(request)
  File "/Users/Insolia/Code/Python/bank_2.0/env/bank_2.0_venv/lib/python3.6/site-packages/django/core/handlers/base.py", line 187, in _get_response
    response = self.process_exception_by_middleware(e, request)
  File "/Users/Insolia/Code/Python/bank_2.0/env/bank_2.0_venv/lib/python3.6/site-packages/django/core/handlers/base.py", line 185, in _get_response
    response = wrapped_callback(request, *callback_args, **callback_kwargs)
  File "/Users/Insolia/Code/Python/bank_2.0/env/bank_2.0_venv/lib/python3.6/site-packages/django/views/decorators/csrf.py", line 58, in wrapped_view
    return view_func(*args, **kwargs)
  File "/Users/Insolia/Code/Python/bank_2.0/bank_app/bank_api/views.py", line 68, in get_students_money
    writer.writerow(Money.objects.all().first().full_info_headers_as_list())
  File "/Users/Insolia/Code/Python/bank_2.0/bank_app/bank/models/Money.py", line 81, in full_info_headers_as_list
    ['receiver_' + x for x in self.receiver.account.full_info_headers_as_list()] + \
AttributeError: 'super' object has no attribute 'full_info_headers_as_list'
ERROR 2017-09-15 22:29:54,867 "GET /bank_api/money/ HTTP/1.1" 500 75353
ERROR 2017-09-15 22:32:24,636 Internal Server Error: /bank_api/money/
Traceback (most recent call last):
  File "/Users/Insolia/Code/Python/bank_2.0/env/bank_2.0_venv/lib/python3.6/site-packages/django/core/handlers/exception.py", line 41, in inner
    response = get_response(request)
  File "/Users/Insolia/Code/Python/bank_2.0/env/bank_2.0_venv/lib/python3.6/site-packages/django/core/handlers/base.py", line 249, in _legacy_get_response
    response = self._get_response(request)
  File "/Users/Insolia/Code/Python/bank_2.0/env/bank_2.0_venv/lib/python3.6/site-packages/django/core/handlers/base.py", line 187, in _get_response
    response = self.process_exception_by_middleware(e, request)
  File "/Users/Insolia/Code/Python/bank_2.0/env/bank_2.0_venv/lib/python3.6/site-packages/django/core/handlers/base.py", line 185, in _get_response
    response = wrapped_callback(request, *callback_args, **callback_kwargs)
  File "/Users/Insolia/Code/Python/bank_2.0/env/bank_2.0_venv/lib/python3.6/site-packages/django/views/decorators/csrf.py", line 58, in wrapped_view
    return view_func(*args, **kwargs)
  File "/Users/Insolia/Code/Python/bank_2.0/bank_app/bank_api/views.py", line 68, in get_students_money
    writer.writerow(Money.objects.all().first().full_info_headers_as_list())
  File "/Users/Insolia/Code/Python/bank_2.0/bank_app/bank/models/Money.py", line 81, in full_info_headers_as_list
    ['receiver_' + x for x in self.receiver.account.full_info_headers_as_list()] + \
TypeError: super() argument 1 must be type, not Money
ERROR 2017-09-15 22:32:24,722 "GET /bank_api/money/ HTTP/1.1" 500 75193
ERROR 2017-09-15 22:32:49,191 Internal Server Error: /bank_api/money/
Traceback (most recent call last):
  File "/Users/Insolia/Code/Python/bank_2.0/env/bank_2.0_venv/lib/python3.6/site-packages/django/core/handlers/exception.py", line 41, in inner
    response = get_response(request)
  File "/Users/Insolia/Code/Python/bank_2.0/env/bank_2.0_venv/lib/python3.6/site-packages/django/core/handlers/base.py", line 249, in _legacy_get_response
    response = self._get_response(request)
  File "/Users/Insolia/Code/Python/bank_2.0/env/bank_2.0_venv/lib/python3.6/site-packages/django/core/handlers/base.py", line 187, in _get_response
    response = self.process_exception_by_middleware(e, request)
  File "/Users/Insolia/Code/Python/bank_2.0/env/bank_2.0_venv/lib/python3.6/site-packages/django/core/handlers/base.py", line 185, in _get_response
    response = wrapped_callback(request, *callback_args, **callback_kwargs)
  File "/Users/Insolia/Code/Python/bank_2.0/env/bank_2.0_venv/lib/python3.6/site-packages/django/views/decorators/csrf.py", line 58, in wrapped_view
    return view_func(*args, **kwargs)
  File "/Users/Insolia/Code/Python/bank_2.0/bank_app/bank_api/views.py", line 68, in get_students_money
    writer.writerow(Money.objects.all().first().full_info_headers_as_list())
  File "/Users/Insolia/Code/Python/bank_2.0/bank_app/bank/models/Money.py", line 81, in full_info_headers_as_list
    ['receiver_' + x for x in self.receiver.account.full_info_headers_as_list()] + \
TypeError: super() argument 1 must be type, not Money
ERROR 2017-09-15 22:32:49,248 "GET /bank_api/money/ HTTP/1.1" 500 75199
ERROR 2018-06-11 16:40:31,699 Internal Server Error: /bank/add_transaction/seminar/
Traceback (most recent call last):
  File "/Users/Insolia/Code/Python/bank_2.0/env/bank_2.0_venv/lib/python3.6/site-packages/django/core/handlers/exception.py", line 41, in inner
    response = get_response(request)
  File "/Users/Insolia/Code/Python/bank_2.0/env/bank_2.0_venv/lib/python3.6/site-packages/django/core/handlers/base.py", line 249, in _legacy_get_response
    response = self._get_response(request)
  File "/Users/Insolia/Code/Python/bank_2.0/env/bank_2.0_venv/lib/python3.6/site-packages/django/core/handlers/base.py", line 187, in _get_response
    response = self.process_exception_by_middleware(e, request)
  File "/Users/Insolia/Code/Python/bank_2.0/env/bank_2.0_venv/lib/python3.6/site-packages/django/core/handlers/base.py", line 185, in _get_response
    response = wrapped_callback(request, *callback_args, **callback_kwargs)
  File "/Users/Insolia/Code/Python/bank_2.0/env/bank_2.0_venv/lib/python3.6/site-packages/django/contrib/auth/decorators.py", line 23, in _wrapped_view
    return view_func(request, *args, **kwargs)
  File "/Users/Insolia/Code/Python/bank_2.0/bank_app/bank/views.py", line 65, in add_transaction
    if formset.is_valid():
  File "/Users/Insolia/Code/Python/bank_2.0/env/bank_2.0_venv/lib/python3.6/site-packages/django/forms/formsets.py", line 321, in is_valid
    self.errors
  File "/Users/Insolia/Code/Python/bank_2.0/env/bank_2.0_venv/lib/python3.6/site-packages/django/forms/formsets.py", line 295, in errors
    self.full_clean()
  File "/Users/Insolia/Code/Python/bank_2.0/env/bank_2.0_venv/lib/python3.6/site-packages/django/forms/formsets.py", line 366, in full_clean
    self.clean()
  File "/Users/Insolia/Code/Python/bank_2.0/bank_app/bank/forms.py", line 281, in clean
    self.add_error('block', "Докладчик уже занимался чем-то в этот блок. Может быть вы перепутали докладчика или блок? \
AttributeError: 'SeminarKernelFormFormSet' object has no attribute 'add_error'
ERROR 2018-06-11 16:40:32,182 "POST /bank/add_transaction/seminar/ HTTP/1.1" 500 347398
ERROR 2018-06-11 16:43:06,705 Internal Server Error: /bank/add_transaction/seminar/
Traceback (most recent call last):
  File "/Users/Insolia/Code/Python/bank_2.0/env/bank_2.0_venv/lib/python3.6/site-packages/django/core/handlers/exception.py", line 41, in inner
    response = get_response(request)
  File "/Users/Insolia/Code/Python/bank_2.0/env/bank_2.0_venv/lib/python3.6/site-packages/django/core/handlers/base.py", line 249, in _legacy_get_response
    response = self._get_response(request)
  File "/Users/Insolia/Code/Python/bank_2.0/env/bank_2.0_venv/lib/python3.6/site-packages/django/core/handlers/base.py", line 187, in _get_response
    response = self.process_exception_by_middleware(e, request)
  File "/Users/Insolia/Code/Python/bank_2.0/env/bank_2.0_venv/lib/python3.6/site-packages/django/core/handlers/base.py", line 185, in _get_response
    response = wrapped_callback(request, *callback_args, **callback_kwargs)
  File "/Users/Insolia/Code/Python/bank_2.0/env/bank_2.0_venv/lib/python3.6/site-packages/django/contrib/auth/decorators.py", line 23, in _wrapped_view
    return view_func(request, *args, **kwargs)
  File "/Users/Insolia/Code/Python/bank_2.0/bank_app/bank/views.py", line 65, in add_transaction
    if formset.is_valid():
  File "/Users/Insolia/Code/Python/bank_2.0/env/bank_2.0_venv/lib/python3.6/site-packages/django/forms/formsets.py", line 321, in is_valid
    self.errors
  File "/Users/Insolia/Code/Python/bank_2.0/env/bank_2.0_venv/lib/python3.6/site-packages/django/forms/formsets.py", line 295, in errors
    self.full_clean()
  File "/Users/Insolia/Code/Python/bank_2.0/env/bank_2.0_venv/lib/python3.6/site-packages/django/forms/formsets.py", line 366, in full_clean
    self.clean()
  File "/Users/Insolia/Code/Python/bank_2.0/bank_app/bank/forms.py", line 282, in clean
    test_attendance.delete()
  File "/Users/Insolia/Code/Python/bank_2.0/env/bank_2.0_venv/lib/python3.6/site-packages/django/db/models/base.py", line 967, in delete
    (self._meta.object_name, self._meta.pk.attname)
AssertionError: Attendance object can't be deleted because its id attribute is set to None.
ERROR 2018-06-11 16:43:07,070 "POST /bank/add_transaction/seminar/ HTTP/1.1" 500 350864
ERROR 2018-06-11 17:01:21,059 Internal Server Error: /bank/add_transaction/fac_attend/
Traceback (most recent call last):
  File "/Users/Insolia/Code/Python/bank_2.0/env/bank_2.0_venv/lib/python3.6/site-packages/django/core/handlers/exception.py", line 41, in inner
    response = get_response(request)
  File "/Users/Insolia/Code/Python/bank_2.0/env/bank_2.0_venv/lib/python3.6/site-packages/django/core/handlers/base.py", line 249, in _legacy_get_response
    response = self._get_response(request)
  File "/Users/Insolia/Code/Python/bank_2.0/env/bank_2.0_venv/lib/python3.6/site-packages/django/core/handlers/base.py", line 187, in _get_response
    response = self.process_exception_by_middleware(e, request)
  File "/Users/Insolia/Code/Python/bank_2.0/env/bank_2.0_venv/lib/python3.6/site-packages/django/core/handlers/base.py", line 185, in _get_response
    response = wrapped_callback(request, *callback_args, **callback_kwargs)
  File "/Users/Insolia/Code/Python/bank_2.0/env/bank_2.0_venv/lib/python3.6/site-packages/django/contrib/auth/decorators.py", line 23, in _wrapped_view
    return view_func(request, *args, **kwargs)
  File "/Users/Insolia/Code/Python/bank_2.0/bank_app/bank/views.py", line 71, in add_transaction
    created_transaction = controller.get_transaction_from_form_data(formset.cleaned_data, update_of)
  File "/Users/Insolia/Code/Python/bank_2.0/bank_app/bank/controls/transaction_controllers/FacAttendTransactionController.py", line 41, in get_transaction_from_form_data
    new_transaction, first_form['block'])
  File "/Users/Insolia/Code/Python/bank_2.0/bank_app/bank/models/Attendance.py", line 26, in new_attendance
    new_att.save()
  File "/Users/Insolia/Code/Python/bank_2.0/env/bank_2.0_venv/lib/python3.6/site-packages/django/db/models/base.py", line 806, in save
    force_update=force_update, update_fields=update_fields)
  File "/Users/Insolia/Code/Python/bank_2.0/env/bank_2.0_venv/lib/python3.6/site-packages/django/db/models/base.py", line 836, in save_base
    updated = self._save_table(raw, cls, force_insert, force_update, using, update_fields)
  File "/Users/Insolia/Code/Python/bank_2.0/env/bank_2.0_venv/lib/python3.6/site-packages/django/db/models/base.py", line 922, in _save_table
    result = self._do_insert(cls._base_manager, using, fields, update_pk, raw)
  File "/Users/Insolia/Code/Python/bank_2.0/env/bank_2.0_venv/lib/python3.6/site-packages/django/db/models/base.py", line 961, in _do_insert
    using=using, raw=raw)
  File "/Users/Insolia/Code/Python/bank_2.0/env/bank_2.0_venv/lib/python3.6/site-packages/django/db/models/manager.py", line 85, in manager_method
    return getattr(self.get_queryset(), name)(*args, **kwargs)
  File "/Users/Insolia/Code/Python/bank_2.0/env/bank_2.0_venv/lib/python3.6/site-packages/django/db/models/query.py", line 1061, in _insert
    return query.get_compiler(using=using).execute_sql(return_id)
  File "/Users/Insolia/Code/Python/bank_2.0/env/bank_2.0_venv/lib/python3.6/site-packages/django/db/models/sql/compiler.py", line 1098, in execute_sql
    for sql, params in self.as_sql():
  File "/Users/Insolia/Code/Python/bank_2.0/env/bank_2.0_venv/lib/python3.6/site-packages/django/db/models/sql/compiler.py", line 1051, in as_sql
    for obj in self.query.objs
  File "/Users/Insolia/Code/Python/bank_2.0/env/bank_2.0_venv/lib/python3.6/site-packages/django/db/models/sql/compiler.py", line 1051, in <listcomp>
    for obj in self.query.objs
  File "/Users/Insolia/Code/Python/bank_2.0/env/bank_2.0_venv/lib/python3.6/site-packages/django/db/models/sql/compiler.py", line 1050, in <listcomp>
    [self.prepare_value(field, self.pre_save_val(field, obj)) for field in fields]
  File "/Users/Insolia/Code/Python/bank_2.0/env/bank_2.0_venv/lib/python3.6/site-packages/django/db/models/sql/compiler.py", line 990, in prepare_value
    value = field.get_db_prep_save(value, connection=self.connection)
  File "/Users/Insolia/Code/Python/bank_2.0/env/bank_2.0_venv/lib/python3.6/site-packages/django/db/models/fields/__init__.py", line 766, in get_db_prep_save
    prepared=False)
  File "/Users/Insolia/Code/Python/bank_2.0/env/bank_2.0_venv/lib/python3.6/site-packages/django/db/models/fields/__init__.py", line 1297, in get_db_prep_value
    value = self.get_prep_value(value)
  File "/Users/Insolia/Code/Python/bank_2.0/env/bank_2.0_venv/lib/python3.6/site-packages/django/db/models/fields/__init__.py", line 1292, in get_prep_value
    return self.to_python(value)
  File "/Users/Insolia/Code/Python/bank_2.0/env/bank_2.0_venv/lib/python3.6/site-packages/django/db/models/fields/__init__.py", line 1267, in to_python
    params={'value': value},
django.core.exceptions.ValidationError: ["'0-06-11' value has an invalid date format. It must be in YYYY-MM-DD format."]
ERROR 2018-06-11 17:01:21,471 "POST /bank/add_transaction/fac_attend/ HTTP/1.1" 500 278189
ERROR 2018-06-11 17:01:33,601 Internal Server Error: /bank/add_transaction/fac_attend/
Traceback (most recent call last):
  File "/Users/Insolia/Code/Python/bank_2.0/env/bank_2.0_venv/lib/python3.6/site-packages/django/db/models/fields/__init__.py", line 1254, in to_python
    parsed = parse_date(value)
  File "/Users/Insolia/Code/Python/bank_2.0/env/bank_2.0_venv/lib/python3.6/site-packages/django/utils/dateparse.py", line 64, in parse_date
    return datetime.date(**kw)
ValueError: year 0 is out of range

During handling of the above exception, another exception occurred:

Traceback (most recent call last):
  File "/Users/Insolia/Code/Python/bank_2.0/env/bank_2.0_venv/lib/python3.6/site-packages/django/core/handlers/exception.py", line 41, in inner
    response = get_response(request)
  File "/Users/Insolia/Code/Python/bank_2.0/env/bank_2.0_venv/lib/python3.6/site-packages/django/core/handlers/base.py", line 249, in _legacy_get_response
    response = self._get_response(request)
  File "/Users/Insolia/Code/Python/bank_2.0/env/bank_2.0_venv/lib/python3.6/site-packages/django/core/handlers/base.py", line 187, in _get_response
    response = self.process_exception_by_middleware(e, request)
  File "/Users/Insolia/Code/Python/bank_2.0/env/bank_2.0_venv/lib/python3.6/site-packages/django/core/handlers/base.py", line 185, in _get_response
    response = wrapped_callback(request, *callback_args, **callback_kwargs)
  File "/Users/Insolia/Code/Python/bank_2.0/env/bank_2.0_venv/lib/python3.6/site-packages/django/contrib/auth/decorators.py", line 23, in _wrapped_view
    return view_func(request, *args, **kwargs)
  File "/Users/Insolia/Code/Python/bank_2.0/bank_app/bank/views.py", line 71, in add_transaction
    created_transaction = controller.get_transaction_from_form_data(formset.cleaned_data, update_of)
  File "/Users/Insolia/Code/Python/bank_2.0/bank_app/bank/controls/transaction_controllers/FacAttendTransactionController.py", line 41, in get_transaction_from_form_data
    new_transaction, first_form['block'])
  File "/Users/Insolia/Code/Python/bank_2.0/bank_app/bank/models/Attendance.py", line 26, in new_attendance
    new_att.save()
  File "/Users/Insolia/Code/Python/bank_2.0/env/bank_2.0_venv/lib/python3.6/site-packages/django/db/models/base.py", line 806, in save
    force_update=force_update, update_fields=update_fields)
  File "/Users/Insolia/Code/Python/bank_2.0/env/bank_2.0_venv/lib/python3.6/site-packages/django/db/models/base.py", line 836, in save_base
    updated = self._save_table(raw, cls, force_insert, force_update, using, update_fields)
  File "/Users/Insolia/Code/Python/bank_2.0/env/bank_2.0_venv/lib/python3.6/site-packages/django/db/models/base.py", line 922, in _save_table
    result = self._do_insert(cls._base_manager, using, fields, update_pk, raw)
  File "/Users/Insolia/Code/Python/bank_2.0/env/bank_2.0_venv/lib/python3.6/site-packages/django/db/models/base.py", line 961, in _do_insert
    using=using, raw=raw)
  File "/Users/Insolia/Code/Python/bank_2.0/env/bank_2.0_venv/lib/python3.6/site-packages/django/db/models/manager.py", line 85, in manager_method
    return getattr(self.get_queryset(), name)(*args, **kwargs)
  File "/Users/Insolia/Code/Python/bank_2.0/env/bank_2.0_venv/lib/python3.6/site-packages/django/db/models/query.py", line 1061, in _insert
    return query.get_compiler(using=using).execute_sql(return_id)
  File "/Users/Insolia/Code/Python/bank_2.0/env/bank_2.0_venv/lib/python3.6/site-packages/django/db/models/sql/compiler.py", line 1098, in execute_sql
    for sql, params in self.as_sql():
  File "/Users/Insolia/Code/Python/bank_2.0/env/bank_2.0_venv/lib/python3.6/site-packages/django/db/models/sql/compiler.py", line 1051, in as_sql
    for obj in self.query.objs
  File "/Users/Insolia/Code/Python/bank_2.0/env/bank_2.0_venv/lib/python3.6/site-packages/django/db/models/sql/compiler.py", line 1051, in <listcomp>
    for obj in self.query.objs
  File "/Users/Insolia/Code/Python/bank_2.0/env/bank_2.0_venv/lib/python3.6/site-packages/django/db/models/sql/compiler.py", line 1050, in <listcomp>
    [self.prepare_value(field, self.pre_save_val(field, obj)) for field in fields]
  File "/Users/Insolia/Code/Python/bank_2.0/env/bank_2.0_venv/lib/python3.6/site-packages/django/db/models/sql/compiler.py", line 990, in prepare_value
    value = field.get_db_prep_save(value, connection=self.connection)
  File "/Users/Insolia/Code/Python/bank_2.0/env/bank_2.0_venv/lib/python3.6/site-packages/django/db/models/fields/__init__.py", line 766, in get_db_prep_save
    prepared=False)
  File "/Users/Insolia/Code/Python/bank_2.0/env/bank_2.0_venv/lib/python3.6/site-packages/django/db/models/fields/__init__.py", line 1297, in get_db_prep_value
    value = self.get_prep_value(value)
  File "/Users/Insolia/Code/Python/bank_2.0/env/bank_2.0_venv/lib/python3.6/site-packages/django/db/models/fields/__init__.py", line 1292, in get_prep_value
    return self.to_python(value)
  File "/Users/Insolia/Code/Python/bank_2.0/env/bank_2.0_venv/lib/python3.6/site-packages/django/db/models/fields/__init__.py", line 1261, in to_python
    params={'value': value},
django.core.exceptions.ValidationError: ["'0000-06-11' value has the correct format (YYYY-MM-DD) but it is an invalid date."]
ERROR 2018-06-11 17:01:33,944 "POST /bank/add_transaction/fac_attend/ HTTP/1.1" 500 286098
ERROR 2018-06-11 17:04:33,440 Internal Server Error: /bank/add_transaction/fac_attend/tmp1032/
Traceback (most recent call last):
  File "/Users/Insolia/Code/Python/bank_2.0/env/bank_2.0_venv/lib/python3.6/site-packages/django/core/handlers/exception.py", line 41, in inner
    response = get_response(request)
  File "/Users/Insolia/Code/Python/bank_2.0/env/bank_2.0_venv/lib/python3.6/site-packages/django/core/handlers/base.py", line 249, in _legacy_get_response
    response = self._get_response(request)
  File "/Users/Insolia/Code/Python/bank_2.0/env/bank_2.0_venv/lib/python3.6/site-packages/django/core/handlers/base.py", line 187, in _get_response
    response = self.process_exception_by_middleware(e, request)
  File "/Users/Insolia/Code/Python/bank_2.0/env/bank_2.0_venv/lib/python3.6/site-packages/django/core/handlers/base.py", line 185, in _get_response
    response = wrapped_callback(request, *callback_args, **callback_kwargs)
  File "/Users/Insolia/Code/Python/bank_2.0/env/bank_2.0_venv/lib/python3.6/site-packages/django/contrib/auth/decorators.py", line 23, in _wrapped_view
    return view_func(request, *args, **kwargs)
  File "/Users/Insolia/Code/Python/bank_2.0/bank_app/bank/views.py", line 71, in add_transaction
    created_transaction = controller.get_transaction_from_form_data(formset.cleaned_data, update_of)
  File "/Users/Insolia/Code/Python/bank_2.0/bank_app/bank/controls/transaction_controllers/FacAttendTransactionController.py", line 41, in get_transaction_from_form_data
    new_transaction, first_form['block'])
  File "/Users/Insolia/Code/Python/bank_2.0/bank_app/bank/models/Attendance.py", line 26, in new_attendance
    new_att.save()
  File "/Users/Insolia/Code/Python/bank_2.0/env/bank_2.0_venv/lib/python3.6/site-packages/django/db/models/base.py", line 806, in save
    force_update=force_update, update_fields=update_fields)
  File "/Users/Insolia/Code/Python/bank_2.0/env/bank_2.0_venv/lib/python3.6/site-packages/django/db/models/base.py", line 836, in save_base
    updated = self._save_table(raw, cls, force_insert, force_update, using, update_fields)
  File "/Users/Insolia/Code/Python/bank_2.0/env/bank_2.0_venv/lib/python3.6/site-packages/django/db/models/base.py", line 922, in _save_table
    result = self._do_insert(cls._base_manager, using, fields, update_pk, raw)
  File "/Users/Insolia/Code/Python/bank_2.0/env/bank_2.0_venv/lib/python3.6/site-packages/django/db/models/base.py", line 961, in _do_insert
    using=using, raw=raw)
  File "/Users/Insolia/Code/Python/bank_2.0/env/bank_2.0_venv/lib/python3.6/site-packages/django/db/models/manager.py", line 85, in manager_method
    return getattr(self.get_queryset(), name)(*args, **kwargs)
  File "/Users/Insolia/Code/Python/bank_2.0/env/bank_2.0_venv/lib/python3.6/site-packages/django/db/models/query.py", line 1061, in _insert
    return query.get_compiler(using=using).execute_sql(return_id)
  File "/Users/Insolia/Code/Python/bank_2.0/env/bank_2.0_venv/lib/python3.6/site-packages/django/db/models/sql/compiler.py", line 1098, in execute_sql
    for sql, params in self.as_sql():
  File "/Users/Insolia/Code/Python/bank_2.0/env/bank_2.0_venv/lib/python3.6/site-packages/django/db/models/sql/compiler.py", line 1051, in as_sql
    for obj in self.query.objs
  File "/Users/Insolia/Code/Python/bank_2.0/env/bank_2.0_venv/lib/python3.6/site-packages/django/db/models/sql/compiler.py", line 1051, in <listcomp>
    for obj in self.query.objs
  File "/Users/Insolia/Code/Python/bank_2.0/env/bank_2.0_venv/lib/python3.6/site-packages/django/db/models/sql/compiler.py", line 1050, in <listcomp>
    [self.prepare_value(field, self.pre_save_val(field, obj)) for field in fields]
  File "/Users/Insolia/Code/Python/bank_2.0/env/bank_2.0_venv/lib/python3.6/site-packages/django/db/models/sql/compiler.py", line 990, in prepare_value
    value = field.get_db_prep_save(value, connection=self.connection)
  File "/Users/Insolia/Code/Python/bank_2.0/env/bank_2.0_venv/lib/python3.6/site-packages/django/db/models/fields/__init__.py", line 766, in get_db_prep_save
    prepared=False)
  File "/Users/Insolia/Code/Python/bank_2.0/env/bank_2.0_venv/lib/python3.6/site-packages/django/db/models/fields/__init__.py", line 1297, in get_db_prep_value
    value = self.get_prep_value(value)
  File "/Users/Insolia/Code/Python/bank_2.0/env/bank_2.0_venv/lib/python3.6/site-packages/django/db/models/fields/__init__.py", line 1292, in get_prep_value
    return self.to_python(value)
  File "/Users/Insolia/Code/Python/bank_2.0/env/bank_2.0_venv/lib/python3.6/site-packages/django/db/models/fields/__init__.py", line 1267, in to_python
    params={'value': value},
django.core.exceptions.ValidationError: ["'2018-0asfd' value has an invalid date format. It must be in YYYY-MM-DD format."]
ERROR 2018-06-11 17:04:33,751 "POST /bank/add_transaction/fac_attend/tmp1032/ HTTP/1.1" 500 279049
